<?xml version="1.0" ?>
<!-- =================================================================================== -->
<!-- |    This document was autogenerated by xacro from puma560.xacro                  | -->
<!-- |    EDITING THIS FILE BY HAND IS NOT RECOMMENDED                                 | -->
<!-- =================================================================================== -->
<!-- UNIMATE Puma 560 Manipulator -->
<robot name="puma560" xmlns:xacro="http://www.ros.org/wiki/xacro">
  <material name="black">
    <color rgba="0.0 0.0 0.0 1.0"/>
  </material>
  <material name="blue">
    <color rgba="0.0 0.0 0.8 1.0"/>
  </material>
  <material name="green">
    <color rgba="0.0 0.8 0.0 1.0"/>
  </material>
  <material name="grey">
    <color rgba="0.2 0.2 0.2 1.0"/>
  </material>
  <material name="red">
    <color rgba="0.8 0.0 0.0 1.0"/>
  </material>
  <material name="red_transparent">
    <color rgba="0.8 0.0 0.0 0.5"/>
  </material>
  <material name="white">
    <color rgba="1.0 1.0 1.0 1.0"/>
  </material>
  <material name="orange">
    <color rgba="1.0 0.423529411765 0.0392156862745 1.0"/>
  </material>
  <material name="brown">
    <color rgba="0.870588235294 0.811764705882 0.764705882353 1.0"/>
  </material>
  <material name="metal">
    <color rgba="0.827450980392 0.827450980392 0.827450980392 1.0"/>
  </material>
  <material name="wood">
    <color rgba="0.803921568627 0.521568627451 0.247058823529 1.0"/>
  </material>
  <!-- Create inertia matrix from parameters for general parts :
  mass[kg] and center of mass[m] 
  inertia_diagonal defined as {Ixx Iyy Izz}[kg.m^2]
  inertia_off_diagonal defined as {Ixy Ixz Iyz}[kg.m^2]
  -->
  <!-- Create inertia matrix from parameters for homogeneous parts : 
  density[kg/m^3], volume[m^3] and center of mass[m]
  inertia_diagonal defined as {Ixx Iyy Izz}[m^4]
  inertia_off_diagonal defined as {Ixy Ixz Iyz}[m^4]
  -->
  <!-- ros_control plugin -->
  <gazebo>
    <plugin filename="libgazebo_ros_control.so" name="gazebo_ros_control">
      <robotNamespace>/puma560</robotNamespace>
      <robotSimType>gazebo_ros_control/DefaultRobotHWSim</robotSimType>
    </plugin>
  </gazebo>
  <!-- Base link-->
  <gazebo reference="puma_base">
    <material>Gazebo/Grey</material>
    <selfCollide>true</selfCollide>
    <static>false</static>
    <turnGravityOff>false</turnGravityOff>
  </gazebo>
  <!-- Link 1 -->
  <gazebo reference="puma_link_1">
    <material>Gazebo/Metal</material>
    <selfCollide>true</selfCollide>
    <static>false</static>
    <turnGravityOff>false</turnGravityOff>
  </gazebo>
  <!-- Link 2 -->
  <gazebo reference="puma_link_2">
    <material>Gazebo/Metal</material>
    <selfCollide>true</selfCollide>
    <static>false</static>
    <turnGravityOff>false</turnGravityOff>
  </gazebo>
  <!-- Link 3 -->
  <gazebo reference="puma_link_3">
    <material>Gazebo/Metal</material>
    <selfCollide>true</selfCollide>
    <static>false</static>
    <turnGravityOff>false</turnGravityOff>
  </gazebo>
  <!-- Link 4 -->
  <gazebo reference="puma_link_4">
    <material>Gazebo/Orange</material>
    <selfCollide>true</selfCollide>
    <static>false</static>
    <turnGravityOff>false</turnGravityOff>
  </gazebo>
  <!-- Link 5 -->
  <gazebo reference="puma_link_5">
    <material>Gazebo/Orange</material>
    <selfCollide>true</selfCollide>
    <static>false</static>
    <turnGravityOff>false</turnGravityOff>
  </gazebo>
  <!-- Link definitions -->
  <link name="world_1"/>
  <joint name="world" type="fixed">
    <parent link="world_1"/>
    <child link="puma_base"/>
    <origin rpy="0 0 0" xyz="0 0 0.54864"/>
    <axis xyz="0 0 1"/>
  </joint>
  <link name="puma_base">
    <visual>
      <origin rpy="0 0 0" xyz="0 0 0"/>
      <geometry>
        <mesh filename="package://puma560/puma_base.stl"/>
      </geometry>
      <material name="grey"/>
    </visual>
    <collision>
      <origin rpy="0 0 0" xyz="0 0 0"/>
      <geometry>
        <mesh filename="package://puma560/puma_base_collision.stl"/>
      </geometry>
    </collision>
    <inertial>
      <origin rpy="0 0 0" xyz="-0.0 0.02196 -0.356146"/>
      <mass value="42.624171"/>
      <inertia ixx="1.485648" ixy="0.0" ixz="0.0" iyy="1.361448" iyz="0.059832" izz="0.433917"/>
    </inertial>
  </link>
  <joint name="joint_1" type="continuous">
    <parent link="puma_base"/>
    <child link="puma_link_1"/>
    <origin rpy="0 0 0" xyz="0 0 0.07493"/>
    <axis xyz="0 0 1"/>
  </joint>
  <link name="puma_link_1">
    <visual>
      <origin rpy="0 0 0" xyz="0 0 0"/>
      <geometry>
        <mesh filename="package://puma560/puma_link_1.stl"/>
      </geometry>
      <material name="metal"/>
    </visual>
    <collision>
      <origin rpy="0 0 0" xyz="0 0 0"/>
      <geometry>
        <mesh filename="package://puma560/puma_link_1_collision.stl"/>
      </geometry>
    </collision>
    <inertial>
      <origin rpy="0 0 0" xyz="-0.0 0.022503 -0.002794"/>
      <mass value="11.972151"/>
      <inertia ixx="0.073791" ixy="0.0" ixz="0.0" iyy="0.035964" iyz="-0.000756" izz="0.073332"/>
    </inertial>
  </link>
  <joint name="joint_2" type="continuous">
    <parent link="puma_link_1"/>
    <child link="puma_link_2"/>
    <origin rpy="1.57079632679 0 0" xyz="0 0.16764 0"/>
    <axis xyz="0 0 1"/>
  </joint>
  <link name="puma_link_2">
    <visual>
      <origin rpy="0 0 0" xyz="0 0 0"/>
      <geometry>
        <mesh filename="package://puma560/puma_link_2.stl"/>
      </geometry>
      <material name="metal"/>
    </visual>
    <collision>
      <origin rpy="0 0 0" xyz="0 0 0"/>
      <geometry>
        <mesh filename="package://puma560/puma_link_2_collision.stl"/>
      </geometry>
    </collision>
    <inertial>
      <origin rpy="0 0 0" xyz="0.082741 4.7e-05 -0.047642"/>
      <mass value="45.485847"/>
      <inertia ixx="0.262521" ixy="2.7e-05" ixz="0.011745" iyy="1.610739" iyz="-0.000135" izz="1.781352"/>
    </inertial>
  </link>
  <joint name="joint_3" type="continuous">
    <parent link="puma_link_2"/>
    <child link="puma_link_3"/>
    <origin rpy="0 0 0" xyz="0.4318 0 0"/>
    <axis xyz="0 0 1"/>
  </joint>
  <link name="puma_link_3">
    <visual>
      <origin rpy="0 0 0" xyz="0 0 0"/>
      <geometry>
        <mesh filename="package://puma560/puma_link_3.stl"/>
      </geometry>
      <material name="metal"/>
    </visual>
    <collision>
      <origin rpy="0 0 0" xyz="0 0 0"/>
      <geometry>
        <mesh filename="package://puma560/puma_link_3_collision.stl"/>
      </geometry>
    </collision>
    <inertial>
      <origin rpy="0 0 0" xyz="0.088782 -1e-06 0.038098"/>
      <mass value="12.426777"/>
      <inertia ixx="0.024813" ixy="0.0" ixz="2.7e-05" iyy="0.223074" iyz="0.0" izz="0.235845"/>
    </inertial>
  </link>
  <joint name="joint_4" type="continuous">
    <parent link="puma_link_3"/>
    <child link="puma_link_4"/>
    <origin rpy="0 1.57079632679 0" xyz="0.35179 0 0.0381 "/>
    <axis xyz="0 0 1"/>
  </joint>
  <link name="puma_link_4">
    <visual>
      <origin rpy="0 0 0" xyz="0 0 0"/>
      <geometry>
        <mesh filename="package://puma560/puma_link_4.stl"/>
      </geometry>
      <material name="orange"/>
    </visual>
    <collision>
      <origin rpy="0 0 0" xyz="0 0 0"/>
      <geometry>
        <mesh filename="package://puma560/puma_link_4_collision.stl"/>
      </geometry>
    </collision>
    <inertial>
      <origin rpy="0 0 0" xyz="-0.0 -0.0 0.047887"/>
      <mass value="1.271133"/>
      <inertia ixx="0.002079" ixy="0.0" ixz="0.0" iyy="0.001998" iyz="0.0" izz="0.001269"/>
    </inertial>
  </link>
  <joint name="joint_5" type="continuous">
    <parent link="puma_link_4"/>
    <child link="puma_link_5"/>
    <origin rpy="0 -1.57079632679 -1.57079632679" xyz="0 0 0.0803 "/>
    <axis xyz="0 0 1"/>
  </joint>
  <link name="puma_link_5">
    <visual>
      <origin rpy="0 0 0" xyz="0 0 0"/>
      <geometry>
        <mesh filename="package://puma560/puma_link_5.stl"/>
      </geometry>
      <material name="orange"/>
    </visual>
    <collision>
      <origin rpy="0 0 0" xyz="0 0 0"/>
      <geometry>
        <mesh filename="package://puma560/puma_link_5_collision.stl"/>
      </geometry>
    </collision>
    <inertial>
      <origin rpy="0 0 0" xyz="0.010974 0.0 0.0"/>
      <mass value="0.209007"/>
      <inertia ixx="5.4e-05" ixy="0.0" ixz="0.0" iyy="0.000108" iyz="0.0" izz="0.000135"/>
    </inertial>
  </link>
  <transmission name="puma_joint_1_transmission">
    <type>transmission_interface/SimpleTransmission</type>
    <joint name="joint_1">
      <hardwareInterface>EffortJointInterface</hardwareInterface>
    </joint>
    <actuator name="puma_joint_1_actuator">
      <hardwareInterface>EffortJointInterface</hardwareInterface>
      <mechanicalReduction>1</mechanicalReduction>
    </actuator>
  </transmission>
  <transmission name="puma_joint_2_transmission">
    <type>transmission_interface/SimpleTransmission</type>
    <joint name="joint_2">
      <hardwareInterface>EffortJointInterface</hardwareInterface>
    </joint>
    <actuator name="puma_joint_2_actuator">
      <hardwareInterface>EffortJointInterface</hardwareInterface>
      <mechanicalReduction>1</mechanicalReduction>
    </actuator>
  </transmission>
  <transmission name="puma_joint_3_transmission">
    <type>transmission_interface/SimpleTransmission</type>
    <joint name="joint_3">
      <hardwareInterface>EffortJointInterface</hardwareInterface>
    </joint>
    <actuator name="puma_joint_3_actuator">
      <hardwareInterface>EffortJointInterface</hardwareInterface>
      <mechanicalReduction>1</mechanicalReduction>
    </actuator>
  </transmission>
  <transmission name="puma_joint_4_transmission">
    <type>transmission_interface/SimpleTransmission</type>
    <joint name="joint_4">
      <hardwareInterface>EffortJointInterface</hardwareInterface>
    </joint>
    <actuator name="puma_joint_4_actuator">
      <hardwareInterface>EffortJointInterface</hardwareInterface>
      <mechanicalReduction>1</mechanicalReduction>
    </actuator>
  </transmission>
  <transmission name="puma_joint_5_transmission">
    <type>transmission_interface/SimpleTransmission</type>
    <joint name="joint_5">
      <hardwareInterface>EffortJointInterface</hardwareInterface>
    </joint>
    <actuator name="puma_joint_5_actuator">
      <hardwareInterface>EffortJointInterface</hardwareInterface>
      <mechanicalReduction>1</mechanicalReduction>
    </actuator>
  </transmission>
</robot>

